Workbook

Sheet Rekap
A1: REKAP STATUS CAPAIAN — SELURUH STANDAR MUTU USS
A4: Kelompok Standar | B4: Jumlah Standar | C4: Tercapai | D4: Melampaui | E4: Belum Tercapai | F4: Menyimpang | G4: Belum Dievaluasi
A5: Standar Pendidikan (13) | B5: =13 -> 13 | C5: =COUNTIF('Standar Pendidikan'!$M$6:$M$18,"Tercapai") -> 0 | D5: =COUNTIF('Standar Pendidikan'!$M$6:$M$18,"Melampaui") -> 0 | E5: =COUNTIF('Standar Pendidikan'!$M$6:$M$18,"Belum Tercapai") -> 0 | F5: =COUNTIF('Standar Pendidikan'!$M$6:$M$18,"Menyimpang") -> 0 | G5: =13-C5-D5-E5-F5 -> 13
A6: Standar Penelitian (8) | B6: =8 -> 8 | C6: =COUNTIF('Standar Penelitian'!$M$6:$M$13,"Tercapai") -> 0 | D6: =COUNTIF('Standar Penelitian'!$M$6:$M$13,"Melampaui") -> 0 | E6: =COUNTIF('Standar Penelitian'!$M$6:$M$13,"Belum Tercapai") -> 0 | F6: =COUNTIF('Standar Penelitian'!$M$6:$M$13,"Menyimpang") -> 0 | G6: =8-C6-D6-E6-F6 -> 8
A7: Standar PkM (8) | B7: =8 -> 8 | C7: =COUNTIF('Standar PkM'!$M$6:$M$13,"Tercapai") -> 0 | D7: =COUNTIF('Standar PkM'!$M$6:$M$13,"Melampaui") -> 0 | E7: =COUNTIF('Standar PkM'!$M$6:$M$13,"Belum Tercapai") -> 0 | F7: =COUNTIF('Standar PkM'!$M$6:$M$13,"Menyimpang") -> 0 | G7: =8-C7-D7-E7-F7 -> 8
A8: Tambahan Penelitian 53/2023 (9) | B8: =9 -> 9 | C8: =COUNTIF('Tambahan Penelitian'!$M$6:$M$14,"Tercapai") -> 0 | D8: =COUNTIF('Tambahan Penelitian'!$M$6:$M$14,"Melampaui") -> 0 | E8: =COUNTIF('Tambahan Penelitian'!$M$6:$M$14,"Belum Tercapai") -> 0 | F8: =COUNTIF('Tambahan Penelitian'!$M$6:$M$14,"Menyimpang") -> 0 | G8: =9-C8-D8-E8-F8 -> 9
A9: Tambahan PkM 53/2023 (12) | B9: =12 -> 12 | C9: =COUNTIF('Tambahan PkM'!$M$6:$M$17,"Tercapai") -> 0 | D9: =COUNTIF('Tambahan PkM'!$M$6:$M$17,"Melampaui") -> 0 | E9: =COUNTIF('Tambahan PkM'!$M$6:$M$17,"Belum Tercapai") -> 0 | F9: =COUNTIF('Tambahan PkM'!$M$6:$M$17,"Menyimpang") -> 0 | G9: =12-C9-D9-E9-F9 -> 12
A10: TOTAL | B10: =SUM(B5:B9) -> 50 | C10: =SUM(C5:C9) -> 0 | D10: =SUM(D5:D9) -> 0 | E10: =SUM(E5:E9) -> 0 | F10: =SUM(F5:F9) -> 0 | G10: =SUM(G5:G9) -> 50
A13: Catatan: tabel di atas terhubung otomatis (formula COUNTIF) ke kolom "Status Capaian" pada sheet Standar Pendidikan / Standar Penelitian / Standar PkM. Perbarui data pada sheet masing-masing, angka di sini ikut terbarui.

Sheet Panduan
A1: TEMPLATE LAPORAN PELAKSANAAN SIKLUS PPEPP SISTEM PENJAMINAN MUTU INTERNAL (SPMI) — UNIVERSITAS SUMATERA SELATAN
B4: Tentang template ini
B5: Template ini membantu USS menyusun laporan pelaksanaan siklus PPEPP (Penetapan, Pelaksanaan, Evaluasi, Pengendalian, Peningkatan) atas ke-29 Standar Mutu inti USS (13 Standar Pendidikan, 8 Standar Penelitian, 8 Standar Pengabdian kepada Masyarakat), sesuai Kebijakan SPMI (KM-USS-01) dan 5 Manual Mutu USS, serta selaras dengan format pelaporan pada Pedoman Teknis Pelaporan dan Verifikasi SPMI Perguruan Tinggi 2026 (Kemdiktisaintek) yang dilaporkan melalui spmi.kemdiktisaintek.go.id dan diverifikasi LLDikti.
B10: Cara mengisi
B11: 1. Buka sheet "Standar Pendidikan", "Standar Penelitian", atau "Standar PkM" — satu baris per standar.
B12: 2. Kolom putih/biru muda (Informasi Standar) sudah terisi sebagai acuan — JANGAN diubah kecuali ada revisi standar resmi.
B13: 3. Isi hanya sel BERWARNA KUNING pada 5 kelompok kolom (Penetapan, Pelaksanaan, Evaluasi, Pengendalian, Peningkatan).
B14: 4. Kolom "Status Capaian" dan "Metode Evaluasi" memakai dropdown — klik sel lalu pilih dari daftar.
B15: 5. Kolom Pengendalian hanya diisi jika Status Capaian = "Belum Tercapai" atau "Menyimpang".
B16: 6. Cek ringkasan otomatis di sheet "Rekap" untuk melihat status seluruh standar sebelum laporan diserahkan ke LPMA / LLDikti.
B17: 7. Sheet "Instrumen AMI" dipakai auditor internal LPMA saat pelaksanaan Audit Mutu Internal (AMAI): 1 baris per standar per tahap PPEPP (P1–P5, total 145 baris untuk 29 standar) — isi Temuan Audit, Kategori Temuan, Rencana Tindak Lanjut (PTK), dan Verifikasi pada sel kuning.
B18: 8. Instrumen AMI berlaku untuk audit di tingkat universitas, fakultas, maupun program studi — isi kolom "Unit Kerja / Fakultas / Program Studi" pada tiap baris. Jika satu standar perlu diaudit di lebih dari satu unit (mis. 4 prodi berbeda), salin (copy-paste) baris standar tsb lalu ubah isian kolom Unit Kerja pada tiap salinannya.
B19: 9. Sheet "Tambahan Penelitian"/"Tambahan PkM" (21 standar Permendikbudristek 53/2023) dan sheet "Dampak Tridharma" bersifat pelengkap — isi dengan mekanisme sama seperti sheet standar inti. Untuk menu "Profil PT" dan "Papan Info PT" di sistem nasional, TIDAK perlu template — datanya otomatis dari PDDikti (lihat tabel "Status pengisian 9 menu" di bawah).
... B22: Legenda warna
C23: Informasi acuan standar — sudah terisi, tidak perlu diubah
C24: Sel yang WAJIB Anda isi dengan data aktual
C25: Baris contoh pengisian (lihat di bawah) — bukan data standar sungguhan
B27: Jadwal acuan (dari Manual Evaluasi SPMI USS & Pedoman Teknis SPMI 2026)
B28: Kegiatan | D28: Frekuensi / Periode
B29: Evaluasi Kebijakan SPMI | D29: Setiap 4 tahun
B30: Evaluasi penerapan SPMI — akademik | D30: Setiap semester (6 bulan), via laporan SIMAK
B31: Evaluasi penerapan SPMI — non-akademik | D31: Setiap tahun
B32: AMAI & EMI (Audit Mutu Akademik Internal / Evaluasi Mutu Internal) | D32: Wajib, minimal 1x/tahun, dikoordinasi LPMA
B33: Verifikasi pelaporan SPMI oleh LLDikti (nasional) | D33: Periode Maret–April, dan Oktober–November (2x/tahun) + sewaktu-waktu
B35: 4 Kategori Status Capaian (dari Manual Evaluasi & Pedoman Teknis SPMI 2026)
B36: Tercapai | C36: Pelaksanaan standar mencapai standar Dikti / target USS yang ditetapkan.
B37: Melampaui | C37: Pelaksanaan standar melampaui target yang ditetapkan.
B38: Belum Tercapai | C38: Pelaksanaan standar belum mencapai target — perlu tindakan Pengendalian.
B39: Menyimpang | C39: Pelaksanaan standar menyimpang dari target — perlu tindakan Pengendalian segera.
B42: Cakupan sheet dalam workbook ini
B43: Rekap | C43: Ringkasan otomatis status capaian seluruh standar (formula, terhubung ke sheet-sheet standar).
B44: Standar Pendidikan / Penelitian / PkM | C44: 29 standar inti USS (13+8+8) — sumber: Kebijakan Mutu & situs web LPMA.
B45: Tambahan Penelitian / Tambahan PkM | C45: 21 standar tambahan berbasis Permendikbudristek 53/2023 (9 Penelitian + 12 PkM), hanya tersedia di Google Drive USS — kode informal, sebagian isi belum tertangkap lengkap dari sumber (lihat subtitle tiap sheet).
B46: Instrumen AMI | C46: Checklist audit internal per standar × 5 tahap PPEPP × unit kerja (mencakup seluruh 50 standar di atas) — untuk Fakultas/Prodi/Universitas.
B47: Instrumen AMI Non-Akademik | C47: Checklist audit untuk unit kerja NON-akademik (BAUK/SDM/Keuangan/Sarpras/dll.), 7 kategori generik × 5 tahap PPEPP — BUKAN standar resmi USS, lihat subtitle sheet.
B48: Dampak Tridharma | C48: Alat bantu menyusun draf narasi untuk menu "Dampak Tridharma" — BELUM ada format baku dari Kemdiktisaintek, jadi sheet ini bersifat opsional/bantu, bukan formulir wajib.
B49: Program Kerja Bulan Mutu | C49: Kalender rangkaian kegiatan penjaminan mutu tahunan (Bulan Mutu) untuk 2023-2026 — 12 kegiatan baku sepanjang siklus PPEPP, tiap tahun punya blok tabel & ringkasan status sendiri (rumus COUNTIF otomatis).
B51: Status pengisian 9 menu Sistem Pelaporan SPMI nasional (spmi.kemdiktisaintek.go.id)
B52: Menu | D52: Cara Pengisian
B53: Home | C53: — (dashboard)
...

Sheet Standar Pendidikan
A1: LAPORAN PELAKSANAAN SIKLUS PPEPP — STANDAR PENDIDIKAN (13 STANDAR)
A2: Universitas Sumatera Selatan — isi hanya sel berwarna kuning. Kolom putih/biru adalah acuan (jangan diubah).
A4: INFORMASI STANDAR | F4: 1. PENETAPAN | H4: 2. PELAKSANAAN | J4: 3. EVALUASI | N4: 4. PENGENDALIAN | Q4: 5. PENINGKATAN
A5: No | B5: Kode Standar | C5: Nama Standar | D5: Target / Indikator Standar (acuan) | E5: Penanggung Jawab (pola baku) | F5: Tanggal Ditetapkan | G5: No. SK / Dokumen Penetapan | H5: Periode Pelaksanaan | I5: Bukti / Dokumen Pelaksanaan | J5: Metode Evaluasi | K5: Tanggal Evaluasi | L5: Capaian Aktual | M5: Status Capaian | N5: Temuan / Penyimpangan | O5: Tindakan Korektif | P5: Tanggal Tindak Lanjut | Q5: Rencana Peningkatan / Revisi Standar | R5: Target Periode Berikutnya
A6: 1 | B6: SM-USS-03-01-01 | C6: Kompetensi Lulusan | D6: IPK minimal 3.0; masa studi maks. 9 semester; lulus tepat waktu ≥50%; wirausaha 30%; TOEFL minimal 400; kesesuaian kerja dgn bidang studi ≥50% | E6: Rektor & WR I, Dekan & WD, Ketua Prodi
A7: 2 | B7: SM-USS-03-01-02 | C7: Isi Pembelajaran | D7: Evaluasi kedalaman/keluasan materi min. 1x/tahun ajaran; peninjauan kurikulum min. 4 tahun sekali | E7: Rektor & WR I, Dekan & WD, Ketua Prodi
A8: 3 | B8: SM-USS-03-01-03 | C8: Proses Pembelajaran | D8: Semua MK punya RPS selaras CPL; kontrak RPS dibagikan awal kuliah; metode PBL/PjBL/studi kasus dsb. | E8: Rektor & WR I, Dekan & WD, Ketua Prodi
A9: 4 | B9: SM-USS-03-01-04 | C9: Penilaian Pembelajaran | D9: Nilai diinput paling lambat 14 hari setelah ujian; prinsip edukatif-otentik-objektif-akuntabel-transparan | E9: Rektor & WR I, Dekan & WD, Ketua Prodi, Dosen
A10: 5 | B10: SM-USS-03-01-05 | C10: Dosen dan Tenaga Kependidikan | D10: Dosen min. S2, jabfung min. Asisten Ahli; rasio dosen:mhs eksakta 1:20 (tol. 1:30), sosial/ekonomi 1:30 (tol. 1:45) | E10: Rektor & WR I, Dekan & WD, Ketua Prodi
A11: 6 | B11: SM-USS-03-01-06 | C11: Sarana dan Prasarana Pembelajaran | D11: 20 pernyataan standar (perabotan, lab, perpustakaan, TIK, ruang kelas dll.) | E11: Rektor & WR I, Dekan & WD, Ketua Prodi, Tim Pengelola Aset
A12: 7 | B12: SM-USS-03-01-07 | C12: Pengelolaan Pembelajaran | D12: Kebijakan pengelolaan seluruh prodi paling lambat 2021; monev tiap semester; lapor PDDikti ganjil ≤15 April, genap ≤15 Oktober | E12: Rektor, WR I, Dekan, Ketua Prodi, BAUK, UPT, LPMA
A13: 8 | B13: SM-USS-03-01-08 | C13: Pembiayaan Pembelajaran | D13: Sistem pencatatan biaya per prodi; evaluasi ketercapaian akhir tahun anggaran; komponen investasi-operasional-personal | E13: Rektor, WR I & WR II, Biro Akademik & Keuangan, LPMA
A14: 9 | B14: SM-USS-03-01-09 | C14: Proses Penerimaan Mahasiswa Baru | D14: Jadwal PMB ditetapkan 1 tahun sebelumnya; info disebar ≤6 bulan sebelum TA baru; kelulusan diumumkan ≤10 hari; target bertahap 80-100% (2019→2021) | E14: WR bidang Akademik, Dekan, Ketua Prodi, BAUK, LPMA
A15: 10 | B15: SM-USS-03-01-10 | C15: Pembelajaran Entrepreneur | D15: Entrepreneur Center per prodi; sarana/media/lab entrepreneur | E15: Rektor & WR I, Dekan & WD, Ketua Prodi
A16: 11 | B16: SM-USS-03-01-11 | C16: Kemampuan Bahasa Inggris | D16: English Learning Center per prodi; sarana/media pendidikan bahasa Inggris | E16: Rektor & WR I, Dekan & WD, Ketua Prodi
A17: 12 | B17: SM-USS-03-01-12 | C17: Kerjasama | D17: MoU/MoA/PKS; prinsip kesetaraan-saling menghormati-saling menguntungkan; bukti laporan/jurnal/prosiding | E17: Pimpinan universitas, seluruh fakultas & unit
A18: 13 | B18: SM-USS-03-01-13 | C18: Merdeka Belajar Kampus Merdeka (MBKM) | D18: 2 semester (40 sks) di luar PT + 1 semester (20 sks) di prodi lain; target Standar MBKM 60%→80% (2020→2021) | E18: WR I, WR II, BAUK, Humas, Dekan, UPMI, LPMA

Sheet Standar Penelitian
A1: LAPORAN PELAKSANAAN SIKLUS PPEPP — STANDAR PENELITIAN (8 STANDAR)
A2: Universitas Sumatera Selatan — isi hanya sel berwarna kuning. Kolom putih/biru adalah acuan (jangan diubah).
A4: INFORMASI STANDAR | F4: 1. PENETAPAN | H4: 2. PELAKSANAAN | J4: 3. EVALUASI | N4: 4. PENGENDALIAN | Q4: 5. PENINGKATAN
A5: No | B5: Kode Standar | C5: Nama Standar | D5: Target / Indikator Standar (acuan) | E5: Penanggung Jawab (pola baku) | F5: Tanggal Ditetapkan | G5: No. SK / Dokumen Penetapan | H5: Periode Pelaksanaan | I5: Bukti / Dokumen Pelaksanaan | J5: Metode Evaluasi | K5: Tanggal Evaluasi | L5: Capaian Aktual | M5: Status Capaian | N5: Temuan / Penyimpangan | O5: Tindakan Korektif | P5: Tanggal Tindak Lanjut | Q5: Rencana Peningkatan / Revisi Standar | R5: Target Periode Berikutnya
A6: 1 | B6: SM-USS-03-02-01 | C6: Hasil Penelitian | D6: Dosen min. 1 penelitian/tahun; mhs S1 min. 1/tahun; kesesuaian RIP >70%→>80% (2020→2021); publikasi >50%→>80% | E6: WR I (pemilik/evaluasi), LPPM (pelaksana), LPMA (pengendalian)
A7: 2 | B7: SM-USS-03-02-02 | C7: Isi Penelitian | D7: Min. 1 penelitian/tahun (dasar & terapan); kesesuaian RIP >50%→>80% (2019→2020) | E7: WR I (pemilik/evaluasi), LPPM (pelaksana), LPMA (pengendalian)
A8: 3 | B8: SM-USS-03-02-03 | C8: Proses Penelitian | D8: Bukti pelaksanaan & review proses >50%→>80%; dokumen perencanaan-pelaksanaan-pelaporan >70%→>90% | E8: WR I (pemilik/evaluasi), LPPM (pelaksana), LPMA (pengendalian)
A9: 4 | B9: SM-USS-03-02-04 | C9: Penilaian Penelitian | D9: 100% LPPM pakai instrumen penilaian terintegrasi; nilai proposal/hasil min. 75; publikasi min. terindeks SINTA-5; tugas akhir setara 6 sks | E9: Rektor, WR I, LPPM, Dekan/Direktur, Ketua Prodi
A10: 5 | B10: SM-USS-03-02-05 | C10: Peneliti | D10: Kesesuaian dgn RIP >80% (2020); verifikasi jadwal >80%; rekomendasi publikasi >88,5%; pengumpulan laporan >90% | E10: WR I (pemilik/evaluasi), LPPM (pelaksana), LPMA (pengendalian)
A11: 6 | B11: SM-USS-03-02-06 | C11: Sarana dan Prasarana Penelitian | D11: Ketersediaan sarana >70%→>95% (2019→2020); fasilitas keselamatan & kesehatan kerja | E11: WR I (pemilik/evaluasi), LPPM (pelaksana), LPMA (pengendalian)
A12: 7 | B12: SM-USS-03-02-07 | C12: Pengelolaan Penelitian | D12: RIP/Renstra/panduan penelitian oleh LPPM; SOP >70%→>90%; laporan tahunan 1x/tahun | E12: WR I (pemilik/evaluasi), LPPM (pelaksana), LPMA (pengendalian)
A13: 8 | B13: SM-USS-03-02-08 | C13: Pendanaan dan Pembiayaan Penelitian | D13: Alokasi dana penelitian internal minimal 7%; target >60%→>80% (2019→2020); tersedia dana pendamping (matching fund) | E13: WR I (pemilik/evaluasi), LPPM (pelaksana), LPMA (pengendalian)

Sheet Standar PkM
A1: LAPORAN PELAKSANAAN SIKLUS PPEPP — STANDAR PENGABDIAN KEPADA MASYARAKAT (8 STANDAR)
A2: Universitas Sumatera Selatan — isi hanya sel berwarna kuning. Kolom putih/biru adalah acuan (jangan diubah).
A4: INFORMASI STANDAR | F4: 1. PENETAPAN | H4: 2. PELAKSANAAN | J4: 3. EVALUASI | N4: 4. PENGENDALIAN | Q4: 5. PENINGKATAN
A5: No | B5: Kode Standar | C5: Nama Standar | D5: Target / Indikator Standar (acuan) | E5: Penanggung Jawab (pola baku) | F5: Tanggal Ditetapkan | G5: No. SK / Dokumen Penetapan | H5: Periode Pelaksanaan | I5: Bukti / Dokumen Pelaksanaan | J5: Metode Evaluasi | K5: Tanggal Evaluasi | L5: Capaian Aktual | M5: Status Capaian | N5: Temuan / Penyimpangan | O5: Tindakan Korektif | P5: Tanggal Tindak Lanjut | Q5: Rencana Peningkatan / Revisi Standar | R5: Target Periode Berikutnya
A6: 1 | B6: SM-USS-03-03-01 | C6: Hasil PkM | D6: Dosen & mhs S1 min. 1 PkM/tahun; kesesuaian RIP >70%→>80% (2019→2021); publikasi >50%→>80% | E6: WR I (pemilik/evaluasi), LPPM (pelaksana), LPMA (pengendalian)
A7: 2 | B7: SM-USS-03-03-02 | C7: Isi PkM | D7: Min. 2x/tahun pelaksanaan terkait kedalaman/keluasan materi; kesesuaian RIP >50%→>80% (2019→2020) | E7: WR I (pemilik/evaluasi), LPPM (pelaksana), LPMA (pengendalian)
A8: 3 | B8: SM-USS-03-03-03 | C8: Proses PkM | D8: Bukti pelaksanaan & review >50%→>80%; dokumen perencanaan-pelaksanaan-pelaporan >70%→>90% | E8: WR I (pemilik/evaluasi), LPPM (pelaksana), LPMA (pengendalian)
A9: 4 | B9: SM-USS-03-03-04 | C9: Penilaian PkM | D9: Kesesuaian rencana/jadwal >50%→>80% (2019→2020-21); rekomendasi perbaikan >70%→>88,5%; pelaporan >80%→>90% | E9: LPPM (pelaksana), WR I (pengawasan)
A10: 5 | B10: SM-USS-03-03-05 | C10: Pelaksana PkM | D10: Ketua peneliti min. S2; capaian dicantumkan >50%→>80%; min. 2 dosen penerima hibah, target >80%→>90% | E10: LPPM (pelaksana), WR I (evaluasi & peningkatan)
A11: 6 | B11: SM-USS-03-03-06 | C11: Sarana dan Prasarana PkM | D11: Ketersediaan sarana >70%→>95% (2019→2020); sarana keselamatan & kesehatan kerja | E11: WR I (pemilik), LPPM (pelaksana), LPMA (pengendalian)
A12: 7 | B12: SM-USS-03-03-07 | C12: Pengelolaan PkM | D12: RIP/Renstra/panduan PkM; SOP >70%→>90%; laporan tahunan 1x/tahun; target implementasi 65%→80% (2020→2021) | E12: LPPM (pelaksana), WR I (pengawasan), LPMA (pengendalian)
A13: 8 | B13: SM-USS-03-03-08 | C13: Pendanaan dan Pembiayaan PkM | D13: Dana eksternal minimal 7% dari total pemasukan, target >60%→>80% (2020→2021); dana internal pendamping >50%→>80% | E13: WR I (pemilik/evaluasi), LPPM (pelaksana), LPMA (pengendalian)

Sheet Tambahan Penelitian
A1: LAPORAN PELAKSANAAN SIKLUS PPEPP — STANDAR TAMBAHAN PENELITIAN — PERMENDIKBUDRISTEK 53/2023 (9 STANDAR)
A2: Universitas Sumatera Selatan — isi hanya sel berwarna kuning. KODE STANDAR bersifat INFORMAL (dokumen sumber Google Drive tidak mencantumkan kode resmi). Sebagian isi Target/Indikator & Penanggung Jawab belum tertangkap lengkap dari dokumen sumber — lihat caveat di sheet Panduan & dokumen proyek ringkasan-dokumen-spmi-uss.md Bagian 6.
A4: INFORMASI STANDAR | F4: 1. PENETAPAN | H4: 2. PELAKSANAAN | J4: 3. EVALUASI | N4: 4. PENGENDALIAN | Q4: 5. PENINGKATAN
A5: No | B5: Kode Standar | C5: Nama Standar | D5: Target / Indikator Standar (acuan) | E5: Penanggung Jawab (pola baku) | F5: Tanggal Ditetapkan | G5: No. SK / Dokumen Penetapan | H5: Periode Pelaksanaan | I5: Bukti / Dokumen Pelaksanaan | J5: Metode Evaluasi | K5: Tanggal Evaluasi | L5: Capaian Aktual | M5: Status Capaian | N5: Temuan / Penyimpangan | O5: Tindakan Korektif | P5: Tanggal Tindak Lanjut | Q5: Rencana Peningkatan / Revisi Standar | R5: Target Periode Berikutnya
A6: 1 | B6: SM-USS-T-PN-01 | C6: Penggunaan TIK Penelitian | D6: Kepala STK pastikan dosen gunakan TIK tiap tahun anggaran; STK & WR II jamin sarana/pembiayaan TIK; Ketua Prodi jamin akses dosen; Tim Pengawasan TIK cek kendala min. 3 bulan sekali | E6: Kepala STK, WR II, Ketua Prodi, Tim Pengawasan TIK
A7: 2 | B7: SM-USS-T-PN-02 | C7: Penugasan Dosen Penelitian | D7: Dosen ajukan proposal sesuai panduan LPPM; LPPM lapor jumlah judul; Rektor terbitkan SK penugasan tiap periode | E7: Dosen, LPPM, Rektor
A8: 3 | B8: SM-USS-T-PN-03 | C8: Pembiayaan Penelitian | D8: USS wajib danai minimal 1 penelitian/tahun via dana internal (APBU/hibah eksternal/kerja sama pihak ketiga); besaran berdasarkan skema & kompleksitas | E8: WR I & WR II, LPPM
A9: 4 | B9: SM-USS-T-PN-04 | C9: Akses Sarana dan Prasarana Penelitian | D9: Prasarana sesuai roadmap & isu strategis (lab riset tematik, fasilitas lapangan, software analisis SPSS/NVivo/MATLAB); alokasi anggaran jelas | E9: WR I, LPPM, unit Sarpras
A10: 5 | B10: SM-USS-T-PN-05 | C10: Penilaian Penelitian (versi 53/2023) | D10: Penilaian edukatif-objektif-akuntabel-transparan, menjunjung otonomi keilmuan | E10: LPPM, reviewer/penilai
A11: 6 | B11: SM-USS-T-PN-06 | C11: Proses Pengawasan Penelitian | D11: Pengawasan berkala kualitas & anggaran; LPPM pastikan dana sesuai rencana; laporan dipertanggungjawabkan ke pimpinan | E11: LPPM, WR I
A12: 7 | B12: SM-USS-T-PN-07 | C12: Proses Pelaksanaan Penelitian (label situs: Pengendalian Kegiatan Penelitian) | D12: Tahapan persiapan–lapangan/lab–analisis–dokumentasi; minimalkan bias & penuhi regulasi nasional/internasional | E12: Peneliti, LPPM
A13: 8 | B13: SM-USS-T-PN-08 | C13: Perencanaan Penelitian | D13: Identifikasi isu strategis, rumusan masalah, metodologi, luaran terukur, selaras RIP/Renstra/prioritas nasional | E13: LPPM, peneliti
A14: 9 | B14: SM-USS-T-PN-09 | C14: Mutu Luaran Penelitian / Relevansi Penelitian | D14: Kepala LPPM jamin pedoman & kesesuaian judul dengan roadmap prodi tiap tahun | E14: Kepala LPPM

Sheet Tambahan PkM
A1: LAPORAN PELAKSANAAN SIKLUS PPEPP — STANDAR TAMBAHAN PkM — PERMENDIKBUDRISTEK 53/2023 (12 STANDAR)
A2: Universitas Sumatera Selatan — isi hanya sel berwarna kuning. KODE STANDAR bersifat INFORMAL (dokumen sumber Google Drive tidak mencantumkan kode resmi). Sebagian isi Target/Indikator & Penanggung Jawab belum tertangkap lengkap dari dokumen sumber — lihat caveat di sheet Panduan & dokumen proyek ringkasan-dokumen-spmi-uss.md Bagian 6.
A4: INFORMASI STANDAR | F4: 1. PENETAPAN | H4: 2. PELAKSANAAN | J4: 3. EVALUASI | N4: 4. PENGENDALIAN | Q4: 5. PENINGKATAN
A5: No | B5: Kode Standar | C5: Nama Standar | D5: Target / Indikator Standar (acuan) | E5: Penanggung Jawab (pola baku) | F5: Tanggal Ditetapkan | G5: No. SK / Dokumen Penetapan | H5: Periode Pelaksanaan | I5: Bukti / Dokumen Pelaksanaan | J5: Metode Evaluasi | K5: Tanggal Evaluasi | L5: Capaian Aktual | M5: Status Capaian | N5: Temuan / Penyimpangan | O5: Tindakan Korektif | P5: Tanggal Tindak Lanjut | Q5: Rencana Peningkatan / Revisi Standar | R5: Target Periode Berikutnya
A6: 1 | B6: SM-USS-T-PKM-01 | C6: Akses Sarana PkM | D6: WR Keuangan/SDM/Sapras/Kerjasama jamin sarana penuhi kriteria minimal & standar mutu-keamanan; peneliti bertanggung jawab atas risiko penggunaan sarana institusi | E6: WR terkait (Keuangan/SDM/Sapras/Kerjasama)
A7: 2 | B7: SM-USS-T-PKM-02 | C7: Prasarana PkM | D7: Sesuai roadmap PkM & isu strategis wilayah (pemberdayaan desa, pertanian, kesehatan, UMKM): ruang pelatihan, lab lapangan, teknologi tepat guna, infrastruktur digital | E7: LPPM, unit Sarpras
A8: 3 | B8: SM-USS-T-PKM-03 | C8: Pembiayaan PkM | D8: Dana seluruh tahapan PkM (perencanaan-pelaksanaan-evaluasi-pelaporan) sesuai prinsip relevansi-efektivitas-efisiensi-akuntabilitas-keberlanjutan | E8: WR I & WR II, LPPM
A9: 4 | B9: SM-USS-T-PKM-04 | C9: Penugasan PkM Dosen | D9: Proposal diajukan paling lambat akhir semester; orisinalitas target 80%; validitas data target 90% | E9: Dosen, LPPM
A10: 5 | B10: SM-USS-T-PKM-05 | C10: Penggunaan TIK PkM | D10: Aspek SDM, infrastruktur TIK, sistem informasi, penggunaan TIK dalam proses pengabdian | E10: Kepala STK, LPPM
A11: 6 | B11: SM-USS-T-PKM-06 | C11: Penilaian PkM | D11: Mengukur dampak sosial-ekonomi hasil riset dosen (kualitas hidup, pengentasan masalah sosial); Kepala LPPM jamin reviewer kompeten tiap tahun | E11: Kepala LPPM
A12: 7 | B12: SM-USS-T-PKM-07 | C12: Perencanaan PkM | D12: Keterarahan, keselarasan Rencana Induk Pengabdian/Renstra, akuntabilitas, kualitas ilmiah, dasar monev | E12: LPPM
A13: 8 | B13: SM-USS-T-PKM-08 | C13: Pelaksanaan PkM | D13: Metodologi tepat, minimalkan bias, ikuti regulasi (paralel dengan versi Penelitian) | E13: Pelaksana PkM, LPPM
A14: 9 | B14: SM-USS-T-PKM-09 | C14: Pengendalian PkM | D14: LPPM jamin keselarasan dengan Roadmap/Renstra; pemantauan-evaluasi berkala wajib; pengawasan anggaran (verifikasi laporan keuangan & realisasi) | E14: LPPM
A15: 10 | B15: SM-USS-T-PKM-10 | C15: Pengawasan PkM | D15: Pengawasan aspek waktu-lokasi-metode-sasaran sesuai proposal; jaga relevansi, etika, efisiensi dana | E15: LPPM, WR I
A16: 11 | B16: SM-USS-T-PKM-11 | C16: Mutu PkM | D16: Luaran PkM (publikasi, produk teknologi/inovasi, HKI/paten); Kepala LPPM jamin pedoman tersedia tiap tahun | E16: Kepala LPPM
A17: 12 | B17: SM-USS-T-PKM-12 | C17: Relevansi PkM (judul asli: Standar Kemanfaatan/Luaran Kemanfaatan Hasil Penelitian) | D17: Dosen/peneliti wajib hasilkan luaran termanfaatkan (teknologi tepat guna/model/kebijakan) dalam 1 semester; mahasiswa terlibat implementasi dalam 1 tahun (≥70% tim); diseminasi selambatnya 6 bulan, min. 1 forum/penelitian | E17: Dosen/peneliti, LPPM

Sheet Instrumen AMI
A1: INSTRUMEN AUDIT MUTU INTERNAL (AMI) — DISUSUN SESUAI 5 TAHAP PPEPP
A2: Universitas Sumatera Selatan — dipakai auditor LPMA saat AMAI, berlaku untuk audit di tingkat universitas, fakultas, maupun program studi. Setiap standar diperiksa pada 5 tahap PPEPP (P1 Penetapan s.d. P5 Peningkatan). Isi kolom "Unit Kerja / Fakultas / Program Studi" sesuai unit yang diaudit; salin baris bila satu standar diaudit di lebih dari satu unit. Isi hanya sel berwarna kuning.
A4: INFORMASI & KRITERIA AUDIT | G4: OBJEK AUDIT | H4: TEMUAN AUDIT | L4: RENCANA TINDAK LANJUT (RTL/PTK) | P4: VERIFIKASI
A5: No | B5: Kelompok Standar | C5: Kode Standar | D5: Nama Standar | E5: Tahap PPEPP | F5: Kriteria / Pertanyaan Audit (acuan) | G5: Unit Kerja / Fakultas / Program Studi (auditee) | H5: Bukti / Dokumen yang Diperiksa | I5: Kondisi / Fakta di Lapangan | J5: Kategori Temuan | K5: Uraian Ketidaksesuaian (jika ada) | L5: Akar Penyebab | M5: Rencana Tindakan Koreksi (PTK) | N5: PIC Tindak Lanjut | O5: Batas Waktu Penyelesaian | P5: Status Verifikasi | Q5: Auditor | R5: Tanggal Audit
A6: 1 | B6: Pendidikan | C6: SM-USS-03-01-01 | D6: Kompetensi Lulusan | E6: 1. PENETAPAN | F6: Apakah Standar "Kompetensi Lulusan" telah ditetapkan secara resmi (SK Rektor), disosialisasikan ke unit terkait, dan target/indikatornya memenuhi atau melampaui SN-Dikti?
A7: 1 | B7: Pendidikan | C7: SM-USS-03-01-01 | D7: Kompetensi Lulusan | E7: 2. PELAKSANAAN | F7: Apakah pelaksanaan Standar "Kompetensi Lulusan" mengacu pada SOP/pedoman pelaksanaan yang berlaku dan didukung bukti/dokumen pelaksanaan yang memadai?
A8: 1 | B8: Pendidikan | C8: SM-USS-03-01-01 | D8: Kompetensi Lulusan | E8: 3. EVALUASI | F8: Apakah evaluasi capaian Standar "Kompetensi Lulusan" dilakukan secara berkala (AMAI/EMI) sesuai jadwal Manual Evaluasi SPMI USS, dan hasilnya terdokumentasi serta dilaporkan?
A9: 1 | B9: Pendidikan | C9: SM-USS-03-01-01 | D9: Kompetensi Lulusan | E9: 4. PENGENDALIAN | F9: Apakah setiap penyimpangan/ketidaktercapaian Standar "Kompetensi Lulusan" ditindaklanjuti dengan tindakan pengendalian (koreksi) yang terdokumentasi dan tepat waktu?
A10: 1 | B10: Pendidikan | C10: SM-USS-03-01-01 | D10: Kompetensi Lulusan | E10: 5. PENINGKATAN | F10: Apakah dilakukan peningkatan/revisi Standar "Kompetensi Lulusan" berdasarkan hasil evaluasi dan pengendalian (benchmarking, penetapan target baru pada RTM)?
A11: 2 | B11: Pendidikan | C11: SM-USS-03-01-02 | D11: Isi Pembelajaran | E11: 1. PENETAPAN | F11: Apakah Standar "Isi Pembelajaran" telah ditetapkan secara resmi (SK Rektor), disosialisasikan ke unit terkait, dan target/indikatornya memenuhi atau melampaui SN-Dikti?
A12: 2 | B12: Pendidikan | C12: SM-USS-03-01-02 | D12: Isi Pembelajaran | E12: 2. PELAKSANAAN | F12: Apakah pelaksanaan Standar "Isi Pembelajaran" mengacu pada SOP/pedoman pelaksanaan yang berlaku dan didukung bukti/dokumen pelaksanaan yang memadai?
A13: 2 | B13: Pendidikan | C13: SM-USS-03-01-02 | D13: Isi Pembelajaran | E13: 3. EVALUASI | F13: Apakah evaluasi capaian Standar "Isi Pembelajaran" dilakukan secara berkala (AMAI/EMI) sesuai jadwal Manual Evaluasi SPMI USS, dan hasilnya terdokumentasi serta dilaporkan?
A14: 2 | B14: Pendidikan | C14: SM-USS-03-01-02 | D14: Isi Pembelajaran | E14: 4. PENGENDALIAN | F14: Apakah setiap penyimpangan/ketidaktercapaian Standar "Isi Pembelajaran" ditindaklanjuti dengan tindakan pengendalian (koreksi) yang terdokumentasi dan tepat waktu?
A15: 2 | B15: Pendidikan | C15: SM-USS-03-01-02 | D15: Isi Pembelajaran | E15: 5. PENINGKATAN | F15: Apakah dilakukan peningkatan/revisi Standar "Isi Pembelajaran" berdasarkan hasil evaluasi dan pengendalian (benchmarking, penetapan target baru pada RTM)?
A16: 3 | B16: Pendidikan | C16: SM-USS-03-01-03 | D16: Proses Pembelajaran | E16: 1. PENETAPAN | F16: Apakah Standar "Proses Pembelajaran" telah ditetapkan secara resmi (SK Rektor), disosialisasikan ke unit terkait, dan target/indikatornya memenuhi atau melampaui SN-Dikti?
A17: 3 | B17: Pendidikan | C17: SM-USS-03-01-03 | D17: Proses Pembelajaran | E17: 2. PELAKSANAAN | F17: Apakah pelaksanaan Standar "Proses Pembelajaran" mengacu pada SOP/pedoman pelaksanaan yang berlaku dan didukung bukti/dokumen pelaksanaan yang memadai?
... A255: 50 | B255: Tambahan PkM | C255: SM-USS-T-PKM-12 | D255: Relevansi PkM (judul asli: Standar Kemanfaatan/Luaran Kemanfaatan Hasil Penelitian) | E255: 5. PENINGKATAN | F255: Apakah dilakukan peningkatan/revisi Standar "Relevansi PkM (judul asli: Standar Kemanfaatan/Luaran Kemanfaatan Hasil Penelitian)" berdasarkan hasil evaluasi dan pengendalian (benchmarking, penetapan target baru pada RTM)?

Sheet Instrumen AMI Non-Akademik
A1: INSTRUMEN AUDIT MUTU INTERNAL — UNIT KERJA NON-AKADEMIK (BUKAN STANDAR RESMI USS)
A2: Universitas Sumatera Selatan — untuk unit kerja non-akademik (BAUK, SDM, Keuangan, Sarpras, Kerjasama, Kemahasiswaan, dll.), BUKAN untuk Fakultas/Prodi (pakai sheet "Instrumen AMI"). 7 kategori di sini disusun GENERIK dari Pedoman Teknis SPMI 2026 — USS belum punya daftar Standar Non-Akademik resmi; sesuaikan dgn kebijakan internal. Audit non-akademik sifatnya tentatif (Manual Evaluasi MM-USS-02-03), minimal 1x/tahun. Isi hanya sel berwarna kuning.
A4: INFORMASI & KRITERIA AUDIT | F4: OBJEK AUDIT | G4: TEMUAN AUDIT | K4: RENCANA TINDAK LANJUT (RTL/PTK) | O4: VERIFIKASI
A5: No | B5: Kode Kategori | C5: Kategori Non-Akademik | D5: Tahap PPEPP | E5: Kriteria / Pertanyaan Audit (acuan) | F5: Unit Kerja / Fakultas / Program Studi (auditee) | G5: Bukti / Dokumen yang Diperiksa | H5: Kondisi / Fakta di Lapangan | I5: Kategori Temuan | J5: Uraian Ketidaksesuaian (jika ada) | K5: Akar Penyebab | L5: Rencana Tindakan Koreksi (PTK) | M5: PIC Tindak Lanjut | N5: Batas Waktu Penyelesaian | O5: Status Verifikasi | P5: Auditor | Q5: Tanggal Audit
A6: 1 | B6: NA-01 | C6: Organisasi dan Tata Kelola / Manajemen | D6: 1. PENETAPAN | E6: Apakah kebijakan/pengaturan "Organisasi dan Tata Kelola / Manajemen" telah ditetapkan secara resmi (SK Rektor/pedoman internal) dan disosialisasikan ke unit kerja terkait?
A7: 1 | B7: NA-01 | C7: Organisasi dan Tata Kelola / Manajemen | D7: 2. PELAKSANAAN | E7: Apakah pelaksanaan "Organisasi dan Tata Kelola / Manajemen" mengacu pada SOP/pedoman yang berlaku dan didukung bukti/dokumen pelaksanaan yang memadai?
A8: 1 | B8: NA-01 | C8: Organisasi dan Tata Kelola / Manajemen | D8: 3. EVALUASI | E8: Apakah dilakukan evaluasi berkala (audit non-akademik) atas "Organisasi dan Tata Kelola / Manajemen" dan hasilnya terdokumentasi serta dilaporkan?
A9: 1 | B9: NA-01 | C9: Organisasi dan Tata Kelola / Manajemen | D9: 4. PENGENDALIAN | E9: Apakah penyimpangan/kekurangan pada "Organisasi dan Tata Kelola / Manajemen" ditindaklanjuti dengan tindakan pengendalian (koreksi) yang terdokumentasi dan tepat waktu?
A10: 1 | B10: NA-01 | C10: Organisasi dan Tata Kelola / Manajemen | D10: 5. PENINGKATAN | E10: Apakah dilakukan peningkatan/perbaikan pada "Organisasi dan Tata Kelola / Manajemen" berdasarkan hasil evaluasi & pengendalian (benchmarking, revisi kebijakan/SOP)?
A11: 2 | B11: NA-02 | C11: Kemahasiswaan | D11: 1. PENETAPAN | E11: Apakah kebijakan/pengaturan "Kemahasiswaan" telah ditetapkan secara resmi (SK Rektor/pedoman internal) dan disosialisasikan ke unit kerja terkait?
A12: 2 | B12: NA-02 | C12: Kemahasiswaan | D12: 2. PELAKSANAAN | E12: Apakah pelaksanaan "Kemahasiswaan" mengacu pada SOP/pedoman yang berlaku dan didukung bukti/dokumen pelaksanaan yang memadai?
A13: 2 | B13: NA-02 | C13: Kemahasiswaan | D13: 3. EVALUASI | E13: Apakah dilakukan evaluasi berkala (audit non-akademik) atas "Kemahasiswaan" dan hasilnya terdokumentasi serta dilaporkan?
A14: 2 | B14: NA-02 | C14: Kemahasiswaan | D14: 4. PENGENDALIAN | E14: Apakah penyimpangan/kekurangan pada "Kemahasiswaan" ditindaklanjuti dengan tindakan pengendalian (koreksi) yang terdokumentasi dan tepat waktu?
A15: 2 | B15: NA-02 | C15: Kemahasiswaan | D15: 5. PENINGKATAN | E15: Apakah dilakukan peningkatan/perbaikan pada "Kemahasiswaan" berdasarkan hasil evaluasi & pengendalian (benchmarking, revisi kebijakan/SOP)?
A16: 3 | B16: NA-03 | C16: Sumber Daya Manusia (SDM / Kepegawaian) | D16: 1. PENETAPAN | E16: Apakah kebijakan/pengaturan "Sumber Daya Manusia (SDM / Kepegawaian)" telah ditetapkan secara resmi (SK Rektor/pedoman internal) dan disosialisasikan ke unit kerja terkait?
A17: 3 | B17: NA-03 | C17: Sumber Daya Manusia (SDM / Kepegawaian) | D17: 2. PELAKSANAAN | E17: Apakah pelaksanaan "Sumber Daya Manusia (SDM / Kepegawaian)" mengacu pada SOP/pedoman yang berlaku dan didukung bukti/dokumen pelaksanaan yang memadai?
... A40: 7 | B40: NA-07 | C40: Kesejahteraan | D40: 5. PENINGKATAN | E40: Apakah dilakukan peningkatan/perbaikan pada "Kesejahteraan" berdasarkan hasil evaluasi & pengendalian (benchmarking, revisi kebijakan/SOP)?

Sheet Dampak Tridharma
A1: DAMPAK TRIDHARMA — DRAF NARASI
A2: Menu baru pada spmi.kemdiktisaintek.go.id. Menurut materi sosialisasi Kemdiktisaintek, menu ini BELUM memiliki format/formulir baku — PT bebas menyusun narasinya sendiri. Sheet ini hanya alat bantu (bukan formulir wajib) untuk menyusun draf narasi per pilar Tridharma sebelum disalin ke sistem. Bukti (gambar/dokumentasi) dicantumkan sebagai TAUTAN di dalam narasi, bukan diunggah sebagai file terpisah.
A4: PENDIDIKAN
A5: Dampak Outstanding / Menonjol (uraian singkat)
A6: Tingkat Dampak (Lokal / Nasional / Internasional)
A7: Keselarasan dengan Visi-Misi-Tujuan-Sasaran (VMTS) USS
A8: Keterkaitan: Siklus PPEPP → Kesiapan Akreditasi → Dampak ke Masyarakat/DUDIKA
A9: Tautan Bukti (link dokumentasi/foto/publikasi, pisahkan dgn koma)
A11: PENELITIAN
A12: Dampak Outstanding / Menonjol (uraian singkat)
A13: Tingkat Dampak (Lokal / Nasional / Internasional)
A14: Keselarasan dengan Visi-Misi-Tujuan-Sasaran (VMTS) USS
... A42: Sumber acuan: materi sosialisasi Kemdiktisaintek “Pelaporan SPMI PT” & “Pelaporan SPMI PT untuk Fasilitator SPMI” (2026) — dirangkum di dokumen proyek ringkasan-pedoman-spmi-2026.md. Karena belum ada format baku, sesuaikan struktur narasi ini dengan kebijakan internal USS.

Sheet Program Kerja Bulan Mutu
A1: PROGRAM KERJA BULAN MUTU — SPMI UNIVERSITAS SUMATERA SELATAN
A2: "Bulan Mutu" adalah periode (biasanya 1 bulan) yang ditetapkan LPMA setiap tahun untuk memusatkan rangkaian kegiatan penjaminan mutu — sosialisasi, evaluasi diri, Audit Mutu Internal (AMAI/EMI & non-akademik), Rapat Tinjauan Manajemen (RTM), hingga pelaporan ke sistem SPMI nasional — dalam satu kalender terpadu, sejalan dengan siklus PPEPP dan jadwal wajib Manual Evaluasi SPMI USS (MM-USS-02-03: AMAI/EMI minimal 1x/tahun). Disarankan dilaksanakan menjelang periode verifikasi LLDikti (Maret–April atau Oktober–November) agar hasil audit siap dilaporkan. Isi hanya sel berwarna kuning; rangkaian kegiatan di bawah adalah usulan baku (sama untuk tiap tahun) — sesuaikan dengan kalender akademik & kebijakan internal USS bila perlu.
A4: BULAN MUTU TAHUN 2023 | G4: Bulan Pelaksanaan:
A5: No | B5: Kegiatan Bulan Mutu | C5: Tahap PPEPP Terkait | D5: Penanggung Jawab (PIC) | E5: Dokumen / Instrumen Terkait | F5: Rencana Waktu (Minggu Ke-) | G5: Tanggal Pelaksanaan (Realisasi) | H5: Status | I5: Catatan
A6: 1 | B6: Rapat Persiapan & Penyusunan Jadwal Bulan Mutu | C6: Penetapan | D6: Kepala LPMA & Tim LPMA | E6: Notulen rapat persiapan
A7: 2 | B7: Penerbitan Surat Tugas Tim Auditor | C7: Penetapan | D7: Rektor / Kepala LPMA | E7: Surat Tugas Tim Audit SPMI USS.docx
A8: 3 | B8: Sosialisasi Standar Mutu & Kebijakan SPMI ke Sivitas Akademika | C8: Pelaksanaan | D8: LPMA bersama Dekan/Ketua Prodi/Kepala Unit | E8: Kebijakan SPMI (KM-USS-01), Standar Mutu terkait
A9: 4 | B9: Pengisian Evaluasi Diri & Bukti Pelaksanaan PPEPP oleh Unit | C9: Pelaksanaan | D9: Fakultas / Program Studi / Unit Kerja | E9: Formulir Bukti Pelaksanaan PPEPP SPMI USS.docx
A10: 5 | B10: Pelaksanaan Audit Mutu Akademik Internal (AMAI/EMI) — Fakultas/Prodi | C10: Evaluasi | D10: Tim Auditor LPMA | E10: Instrumen AMI SPMI USS.docx / sheet "Instrumen AMI"
A11: 6 | B11: Pelaksanaan Audit Mutu Internal Unit Non-Akademik | C11: Evaluasi | D11: Tim Auditor LPMA | E11: Instrumen AMI Non-Akademik SPMI USS.docx / sheet "Instrumen AMI Non-Akademik"
A12: 7 | B12: Penyusunan Laporan Hasil AMAI/EMI | C12: Evaluasi | D12: Ketua Tim Auditor | E12: Laporan Hasil AMAI-EMI SPMI USS.docx
A13: 8 | B13: Penerbitan Permintaan Tindakan Korektif (PTK) atas Temuan | C13: Pengendalian | D13: LPMA / Auditor Penanggung Jawab | E13: Permintaan Tindakan Korektif (PTK) SPMI USS.docx
A14: 9 | B14: Rapat Tinjauan Manajemen (RTM) | C14: Pengendalian | D14: Rektor & Pimpinan Universitas | E14: Berita Acara RTM SPMI USS.docx
A15: 10 | B15: Pemantauan Tindak Lanjut & Penyusunan Laporan Tindak Lanjut (LTL) | C15: Pengendalian | D15: Unit Terkait & LPMA | E15: Laporan Tindak Lanjut (LTL) SPMI USS.docx
A16: 11 | B16: Pelaporan Hasil ke Sistem SPMI Nasional (spmi.kemdiktisaintek.go.id) | C16: Peningkatan | D16: LPMA | E16: Seluruh dokumen di atas
A17: 12 | B17: Evaluasi Pelaksanaan Bulan Mutu & Rencana Perbaikan Tahun Berikutnya | C17: Peningkatan | D17: Kepala LPMA & Pimpinan Universitas | E17: Notulen evaluasi / rekomendasi RTM
A18: Ringkasan Status — Bulan Mutu 2023 | C18: ="Terlaksana Sesuai Rencana: "&COUNTIF(H6:H17,"Terlaksana Sesuai Rencana")&" | Tertunda: "&COUNTIF(H6:H17,"Terlaksana - Tertunda")&" | Belum Dilaksanakan: "&COUNTIF(H6:H17,"Belum Dilaksanakan")&" | Dibatalkan: "&COUNTIF(H6:H17,"Dibatalkan")&" (dari "&(17-6+1)&" kegiatan)" -> Terlaksana Sesuai Rencana: 0 | Tertunda: 0 | Belum Dilaksanakan: 0 | Dibatalkan: 0 (dari 12 kegiatan)
A20: BULAN MUTU TAHUN 2024 | G20: Bulan Pelaksanaan:
A21: No | B21: Kegiatan Bulan Mutu | C21: Tahap PPEPP Terkait | D21: Penanggung Jawab (PIC) | E21: Dokumen / Instrumen Terkait | F21: Rencana Waktu (Minggu Ke-) | G21: Tanggal Pelaksanaan (Realisasi) | H21: Status | I21: Catatan
A22: 1 | B22: Rapat Persiapan & Penyusunan Jadwal Bulan Mutu | C22: Penetapan | D22: Kepala LPMA & Tim LPMA | E22: Notulen rapat persiapan
A23: 2 | B23: Penerbitan Surat Tugas Tim Auditor | C23: Penetapan | D23: Rektor / Kepala LPMA | E23: Surat Tugas Tim Audit SPMI USS.docx
A24: 3 | B24: Sosialisasi Standar Mutu & Kebijakan SPMI ke Sivitas Akademika | C24: Pelaksanaan | D24: LPMA bersama Dekan/Ketua Prodi/Kepala Unit | E24: Kebijakan SPMI (KM-USS-01), Standar Mutu terkait
A25: 4 | B25: Pengisian Evaluasi Diri & Bukti Pelaksanaan PPEPP oleh Unit | C25: Pelaksanaan | D25: Fakultas / Program Studi / Unit Kerja | E25: Formulir Bukti Pelaksanaan PPEPP SPMI USS.docx
A26: 5 | B26: Pelaksanaan Audit Mutu Akademik Internal (AMAI/EMI) — Fakultas/Prodi | C26: Evaluasi | D26: Tim Auditor LPMA | E26: Instrumen AMI SPMI USS.docx / sheet "Instrumen AMI"
A27: 6 | B27: Pelaksanaan Audit Mutu Internal Unit Non-Akademik | C27: Evaluasi | D27: Tim Auditor LPMA | E27: Instrumen AMI Non-Akademik SPMI USS.docx / sheet "Instrumen AMI Non-Akademik"
A28: 7 | B28: Penyusunan Laporan Hasil AMAI/EMI | C28: Evaluasi | D28: Ketua Tim Auditor | E28: Laporan Hasil AMAI-EMI SPMI USS.docx
A29: 8 | B29: Penerbitan Permintaan Tindakan Korektif (PTK) atas Temuan | C29: Pengendalian | D29: LPMA / Auditor Penanggung Jawab | E29: Permintaan Tindakan Korektif (PTK) SPMI USS.docx
A30: 9 | B30: Rapat Tinjauan Manajemen (RTM) | C30: Pengendalian | D30: Rektor & Pimpinan Universitas | E30: Berita Acara RTM SPMI USS.docx
A31: 10 | B31: Pemantauan Tindak Lanjut & Penyusunan Laporan Tindak Lanjut (LTL) | C31: Pengendalian | D31: Unit Terkait & LPMA | E31: Laporan Tindak Lanjut (LTL) SPMI USS.docx
A32: 11 | B32: Pelaporan Hasil ke Sistem SPMI Nasional (spmi.kemdiktisaintek.go.id) | C32: Peningkatan | D32: LPMA | E32: Seluruh dokumen di atas
A33: 12 | B33: Evaluasi Pelaksanaan Bulan Mutu & Rencana Perbaikan Tahun Berikutnya | C33: Peningkatan | D33: Kepala LPMA & Pimpinan Universitas | E33: Notulen evaluasi / rekomendasi RTM
A34: Ringkasan Status — Bulan Mutu 2024 | C34: ="Terlaksana Sesuai Rencana: "&COUNTIF(H22:H33,"Terlaksana Sesuai Rencana")&" | Tertunda: "&COUNTIF(H22:H33,"Terlaksana - Tertunda")&" | Belum Dilaksanakan: "&COUNTIF(H22:H33,"Belum Dilaksanakan")&" | Dibatalkan: "&COUNTIF(H22:H33,"Dibatalkan")&" (dari "&(33-22+1)&" kegiatan)" -> Terlaksana Sesuai Rencana: 0 | Tertunda: 0 | Belum Dilaksanakan: 0 | Dibatalkan: 0 (dari 12 kegiatan)
A36: BULAN MUTU TAHUN 2025 | G36: Bulan Pelaksanaan:
A37: No | B37: Kegiatan Bulan Mutu | C37: Tahap PPEPP Terkait | D37: Penanggung Jawab (PIC) | E37: Dokumen / Instrumen Terkait | F37: Rencana Waktu (Minggu Ke-) | G37: Tanggal Pelaksanaan (Realisasi) | H37: Status | I37: Catatan
A38: 1 | B38: Rapat Persiapan & Penyusunan Jadwal Bulan Mutu | C38: Penetapan | D38: Kepala LPMA & Tim LPMA | E38: Notulen rapat persiapan
A39: 2 | B39: Penerbitan Surat Tugas Tim Auditor | C39: Penetapan | D39: Rektor / Kepala LPMA | E39: Surat Tugas Tim Audit SPMI USS.docx
A40: 3 | B40: Sosialisasi Standar Mutu & Kebijakan SPMI ke Sivitas Akademika | C40: Pelaksanaan | D40: LPMA bersama Dekan/Ketua Prodi/Kepala Unit | E40: Kebijakan SPMI (KM-USS-01), Standar Mutu terkait
A41: 4 | B41: Pengisian Evaluasi Diri & Bukti Pelaksanaan PPEPP oleh Unit | C41: Pelaksanaan | D41: Fakultas / Program Studi / Unit Kerja | E41: Formulir Bukti Pelaksanaan PPEPP SPMI USS.docx
A42: 5 | B42: Pelaksanaan Audit Mutu Akademik Internal (AMAI/EMI) — Fakultas/Prodi | C42: Evaluasi | D42: Tim Auditor LPMA | E42: Instrumen AMI SPMI USS.docx / sheet "Instrumen AMI"
A43: 6 | B43: Pelaksanaan Audit Mutu Internal Unit Non-Akademik | C43: Evaluasi | D43: Tim Auditor LPMA | E43: Instrumen AMI Non-Akademik SPMI USS.docx / sheet "Instrumen AMI Non-Akademik"
...
